2019-01-31 14:47:01,195 INFO: Microblog startup [in /home/yani/Documents/TA/SIA/microblog/app/__init__.py:89]
2019-01-31 14:47:07,376 INFO: Microblog startup [in /home/yani/Documents/TA/SIA/microblog/app/__init__.py:89]
2019-01-31 14:47:10,440 ERROR: Exception on / [GET] [in /home/yani/.local/lib/python2.7/site-packages/flask/app.py:1761]
Traceback (most recent call last):
  File "/home/yani/.local/lib/python2.7/site-packages/flask/app.py", line 2292, in wsgi_app
    response = self.full_dispatch_request()
  File "/home/yani/.local/lib/python2.7/site-packages/flask/app.py", line 1815, in full_dispatch_request
    rv = self.handle_user_exception(e)
  File "/home/yani/.local/lib/python2.7/site-packages/flask/app.py", line 1718, in handle_user_exception
    reraise(exc_type, exc_value, tb)
  File "/home/yani/.local/lib/python2.7/site-packages/flask/app.py", line 1811, in full_dispatch_request
    rv = self.preprocess_request()
  File "/home/yani/.local/lib/python2.7/site-packages/flask/app.py", line 2087, in preprocess_request
    rv = func()
  File "/home/yani/Documents/TA/SIA/microblog/app/main/routes.py", line 16, in before_request
    if current_user.is_authenticated:
  File "/home/yani/.local/lib/python2.7/site-packages/werkzeug/local.py", line 347, in __getattr__
    return getattr(self._get_current_object(), name)
  File "/home/yani/.local/lib/python2.7/site-packages/werkzeug/local.py", line 306, in _get_current_object
    return self.__local()
  File "/home/yani/.local/lib/python2.7/site-packages/flask_login/utils.py", line 26, in <lambda>
    current_user = LocalProxy(lambda: _get_user())
  File "/home/yani/.local/lib/python2.7/site-packages/flask_login/utils.py", line 302, in _get_user
    current_app.login_manager._load_user()
  File "/home/yani/.local/lib/python2.7/site-packages/flask_login/login_manager.py", line 317, in _load_user
    return self.reload_user()
  File "/home/yani/.local/lib/python2.7/site-packages/flask_login/login_manager.py", line 279, in reload_user
    user = self.user_callback(user_id)
  File "/home/yani/Documents/TA/SIA/microblog/app/models.py", line 240, in load_user
    return User.query.get(int(id))
  File "/home/yani/.local/lib/python2.7/site-packages/sqlalchemy/orm/query.py", line 864, in get
    return self._get_impl(ident, loading.load_on_ident)
  File "/home/yani/.local/lib/python2.7/site-packages/sqlalchemy/orm/query.py", line 897, in _get_impl
    return fallback_fn(self, key)
  File "/home/yani/.local/lib/python2.7/site-packages/sqlalchemy/orm/loading.py", line 223, in load_on_ident
    return q.one()
  File "/home/yani/.local/lib/python2.7/site-packages/sqlalchemy/orm/query.py", line 2814, in one
    ret = self.one_or_none()
  File "/home/yani/.local/lib/python2.7/site-packages/sqlalchemy/orm/query.py", line 2784, in one_or_none
    ret = list(self)
  File "/home/yani/.local/lib/python2.7/site-packages/sqlalchemy/orm/query.py", line 2855, in __iter__
    return self._execute_and_instances(context)
  File "/home/yani/.local/lib/python2.7/site-packages/sqlalchemy/orm/query.py", line 2878, in _execute_and_instances
    result = conn.execute(querycontext.statement, self._params)
  File "/home/yani/.local/lib/python2.7/site-packages/sqlalchemy/engine/base.py", line 945, in execute
    return meth(self, multiparams, params)
  File "/home/yani/.local/lib/python2.7/site-packages/sqlalchemy/sql/elements.py", line 263, in _execute_on_connection
    return connection._execute_clauseelement(self, multiparams, params)
  File "/home/yani/.local/lib/python2.7/site-packages/sqlalchemy/engine/base.py", line 1053, in _execute_clauseelement
    compiled_sql, distilled_params
  File "/home/yani/.local/lib/python2.7/site-packages/sqlalchemy/engine/base.py", line 1189, in _execute_context
    context)
  File "/home/yani/.local/lib/python2.7/site-packages/sqlalchemy/engine/base.py", line 1402, in _handle_dbapi_exception
    exc_info
  File "/home/yani/.local/lib/python2.7/site-packages/sqlalchemy/util/compat.py", line 203, in raise_from_cause
    reraise(type(exception), exception, tb=exc_tb, cause=cause)
  File "/home/yani/.local/lib/python2.7/site-packages/sqlalchemy/engine/base.py", line 1182, in _execute_context
    context)
  File "/home/yani/.local/lib/python2.7/site-packages/sqlalchemy/engine/default.py", line 470, in do_execute
    cursor.execute(statement, parameters)
OperationalError: (sqlite3.OperationalError) no such table: user [SQL: u'SELECT user.id AS user_id, user.username AS user_username, user.email AS user_email, user.password_hash AS user_password_hash, user.about_me AS user_about_me, user.last_seen AS user_last_seen, user.token AS user_token, user.token_expiration AS user_token_expiration, user.last_message_read_time AS user_last_message_read_time \nFROM user \nWHERE user.id = ?'] [parameters: (3,)]
2019-01-31 14:47:12,397 ERROR: Exception on / [GET] [in /home/yani/.local/lib/python2.7/site-packages/flask/app.py:1761]
Traceback (most recent call last):
  File "/home/yani/.local/lib/python2.7/site-packages/flask/app.py", line 2292, in wsgi_app
    response = self.full_dispatch_request()
  File "/home/yani/.local/lib/python2.7/site-packages/flask/app.py", line 1815, in full_dispatch_request
    rv = self.handle_user_exception(e)
  File "/home/yani/.local/lib/python2.7/site-packages/flask/app.py", line 1718, in handle_user_exception
    reraise(exc_type, exc_value, tb)
  File "/home/yani/.local/lib/python2.7/site-packages/flask/app.py", line 1811, in full_dispatch_request
    rv = self.preprocess_request()
  File "/home/yani/.local/lib/python2.7/site-packages/flask/app.py", line 2087, in preprocess_request
    rv = func()
  File "/home/yani/Documents/TA/SIA/microblog/app/main/routes.py", line 16, in before_request
    if current_user.is_authenticated:
  File "/home/yani/.local/lib/python2.7/site-packages/werkzeug/local.py", line 347, in __getattr__
    return getattr(self._get_current_object(), name)
  File "/home/yani/.local/lib/python2.7/site-packages/werkzeug/local.py", line 306, in _get_current_object
    return self.__local()
  File "/home/yani/.local/lib/python2.7/site-packages/flask_login/utils.py", line 26, in <lambda>
    current_user = LocalProxy(lambda: _get_user())
  File "/home/yani/.local/lib/python2.7/site-packages/flask_login/utils.py", line 302, in _get_user
    current_app.login_manager._load_user()
  File "/home/yani/.local/lib/python2.7/site-packages/flask_login/login_manager.py", line 317, in _load_user
    return self.reload_user()
  File "/home/yani/.local/lib/python2.7/site-packages/flask_login/login_manager.py", line 279, in reload_user
    user = self.user_callback(user_id)
  File "/home/yani/Documents/TA/SIA/microblog/app/models.py", line 240, in load_user
    return User.query.get(int(id))
  File "/home/yani/.local/lib/python2.7/site-packages/sqlalchemy/orm/query.py", line 864, in get
    return self._get_impl(ident, loading.load_on_ident)
  File "/home/yani/.local/lib/python2.7/site-packages/sqlalchemy/orm/query.py", line 897, in _get_impl
    return fallback_fn(self, key)
  File "/home/yani/.local/lib/python2.7/site-packages/sqlalchemy/orm/loading.py", line 223, in load_on_ident
    return q.one()
  File "/home/yani/.local/lib/python2.7/site-packages/sqlalchemy/orm/query.py", line 2814, in one
    ret = self.one_or_none()
  File "/home/yani/.local/lib/python2.7/site-packages/sqlalchemy/orm/query.py", line 2784, in one_or_none
    ret = list(self)
  File "/home/yani/.local/lib/python2.7/site-packages/sqlalchemy/orm/query.py", line 2855, in __iter__
    return self._execute_and_instances(context)
  File "/home/yani/.local/lib/python2.7/site-packages/sqlalchemy/orm/query.py", line 2878, in _execute_and_instances
    result = conn.execute(querycontext.statement, self._params)
  File "/home/yani/.local/lib/python2.7/site-packages/sqlalchemy/engine/base.py", line 945, in execute
    return meth(self, multiparams, params)
  File "/home/yani/.local/lib/python2.7/site-packages/sqlalchemy/sql/elements.py", line 263, in _execute_on_connection
    return connection._execute_clauseelement(self, multiparams, params)
  File "/home/yani/.local/lib/python2.7/site-packages/sqlalchemy/engine/base.py", line 1053, in _execute_clauseelement
    compiled_sql, distilled_params
  File "/home/yani/.local/lib/python2.7/site-packages/sqlalchemy/engine/base.py", line 1189, in _execute_context
    context)
  File "/home/yani/.local/lib/python2.7/site-packages/sqlalchemy/engine/base.py", line 1402, in _handle_dbapi_exception
    exc_info
  File "/home/yani/.local/lib/python2.7/site-packages/sqlalchemy/util/compat.py", line 203, in raise_from_cause
    reraise(type(exception), exception, tb=exc_tb, cause=cause)
  File "/home/yani/.local/lib/python2.7/site-packages/sqlalchemy/engine/base.py", line 1182, in _execute_context
    context)
  File "/home/yani/.local/lib/python2.7/site-packages/sqlalchemy/engine/default.py", line 470, in do_execute
    cursor.execute(statement, parameters)
OperationalError: (sqlite3.OperationalError) no such table: user [SQL: u'SELECT user.id AS user_id, user.username AS user_username, user.email AS user_email, user.password_hash AS user_password_hash, user.about_me AS user_about_me, user.last_seen AS user_last_seen, user.token AS user_token, user.token_expiration AS user_token_expiration, user.last_message_read_time AS user_last_message_read_time \nFROM user \nWHERE user.id = ?'] [parameters: (3,)]
2019-01-31 15:07:39,085 INFO: Microblog startup [in /home/yani/Documents/TA/SIA/microblog/app/__init__.py:89]
