2019-01-31 15:08:24,977 ERROR: Exception on /auth/register [POST] [in /home/yani/.local/lib/python2.7/site-packages/flask/app.py:1761]
Traceback (most recent call last):
  File "/home/yani/.local/lib/python2.7/site-packages/flask/app.py", line 2292, in wsgi_app
    response = self.full_dispatch_request()
  File "/home/yani/.local/lib/python2.7/site-packages/flask/app.py", line 1815, in full_dispatch_request
    rv = self.handle_user_exception(e)
  File "/home/yani/.local/lib/python2.7/site-packages/flask/app.py", line 1718, in handle_user_exception
    reraise(exc_type, exc_value, tb)
  File "/home/yani/.local/lib/python2.7/site-packages/flask/app.py", line 1813, in full_dispatch_request
    rv = self.dispatch_request()
  File "/home/yani/.local/lib/python2.7/site-packages/flask/app.py", line 1799, in dispatch_request
    return self.view_functions[rule.endpoint](**req.view_args)
  File "/home/yani/Documents/TA/SIA/microblog/app/auth/routes.py", line 42, in register
    if form.validate_on_submit():
  File "/home/yani/.local/lib/python2.7/site-packages/flask_wtf/form.py", line 101, in validate_on_submit
    return self.is_submitted() and self.validate()
  File "/home/yani/.local/lib/python2.7/site-packages/wtforms/form.py", line 310, in validate
    return super(Form, self).validate(extra)
  File "/home/yani/.local/lib/python2.7/site-packages/wtforms/form.py", line 152, in validate
    if not field.validate(self, extra):
  File "/home/yani/.local/lib/python2.7/site-packages/wtforms/fields/core.py", line 204, in validate
    stop_validation = self._run_validation_chain(form, chain)
  File "/home/yani/.local/lib/python2.7/site-packages/wtforms/fields/core.py", line 224, in _run_validation_chain
    validator(form, self)
  File "/home/yani/Documents/TA/SIA/microblog/app/auth/forms.py", line 25, in validate_username
    user = User.query.filter_by(username=username.data).first()
  File "/home/yani/.local/lib/python2.7/site-packages/sqlalchemy/orm/query.py", line 2755, in first
    ret = list(self[0:1])
  File "/home/yani/.local/lib/python2.7/site-packages/sqlalchemy/orm/query.py", line 2547, in __getitem__
    return list(res)
  File "/home/yani/.local/lib/python2.7/site-packages/sqlalchemy/orm/query.py", line 2855, in __iter__
    return self._execute_and_instances(context)
  File "/home/yani/.local/lib/python2.7/site-packages/sqlalchemy/orm/query.py", line 2878, in _execute_and_instances
    result = conn.execute(querycontext.statement, self._params)
  File "/home/yani/.local/lib/python2.7/site-packages/sqlalchemy/engine/base.py", line 945, in execute
    return meth(self, multiparams, params)
  File "/home/yani/.local/lib/python2.7/site-packages/sqlalchemy/sql/elements.py", line 263, in _execute_on_connection
    return connection._execute_clauseelement(self, multiparams, params)
  File "/home/yani/.local/lib/python2.7/site-packages/sqlalchemy/engine/base.py", line 1053, in _execute_clauseelement
    compiled_sql, distilled_params
  File "/home/yani/.local/lib/python2.7/site-packages/sqlalchemy/engine/base.py", line 1189, in _execute_context
    context)
  File "/home/yani/.local/lib/python2.7/site-packages/sqlalchemy/engine/base.py", line 1402, in _handle_dbapi_exception
    exc_info
  File "/home/yani/.local/lib/python2.7/site-packages/sqlalchemy/util/compat.py", line 203, in raise_from_cause
    reraise(type(exception), exception, tb=exc_tb, cause=cause)
  File "/home/yani/.local/lib/python2.7/site-packages/sqlalchemy/engine/base.py", line 1182, in _execute_context
    context)
  File "/home/yani/.local/lib/python2.7/site-packages/sqlalchemy/engine/default.py", line 470, in do_execute
    cursor.execute(statement, parameters)
OperationalError: (sqlite3.OperationalError) no such table: user [SQL: u'SELECT user.id AS user_id, user.username AS user_username, user.email AS user_email, user.password_hash AS user_password_hash, user.about_me AS user_about_me, user.last_seen AS user_last_seen, user.token AS user_token, user.token_expiration AS user_token_expiration, user.last_message_read_time AS user_last_message_read_time \nFROM user \nWHERE user.username = ?\n LIMIT ? OFFSET ?'] [parameters: (u'helloLab', 1, 0)]
2019-01-31 15:09:34,473 INFO: Microblog startup [in /home/yani/Documents/TA/SIA/microblog/app/__init__.py:89]
2019-01-31 15:09:56,794 ERROR: Exception on /auth/register [POST] [in /home/yani/.local/lib/python2.7/site-packages/flask/app.py:1761]
Traceback (most recent call last):
  File "/home/yani/.local/lib/python2.7/site-packages/flask/app.py", line 2292, in wsgi_app
    response = self.full_dispatch_request()
  File "/home/yani/.local/lib/python2.7/site-packages/flask/app.py", line 1815, in full_dispatch_request
    rv = self.handle_user_exception(e)
  File "/home/yani/.local/lib/python2.7/site-packages/flask/app.py", line 1718, in handle_user_exception
    reraise(exc_type, exc_value, tb)
  File "/home/yani/.local/lib/python2.7/site-packages/flask/app.py", line 1813, in full_dispatch_request
    rv = self.dispatch_request()
  File "/home/yani/.local/lib/python2.7/site-packages/flask/app.py", line 1799, in dispatch_request
    return self.view_functions[rule.endpoint](**req.view_args)
  File "/home/yani/Documents/TA/SIA/microblog/app/auth/routes.py", line 42, in register
    if form.validate_on_submit():
  File "/home/yani/.local/lib/python2.7/site-packages/flask_wtf/form.py", line 101, in validate_on_submit
    return self.is_submitted() and self.validate()
  File "/home/yani/.local/lib/python2.7/site-packages/wtforms/form.py", line 310, in validate
    return super(Form, self).validate(extra)
  File "/home/yani/.local/lib/python2.7/site-packages/wtforms/form.py", line 152, in validate
    if not field.validate(self, extra):
  File "/home/yani/.local/lib/python2.7/site-packages/wtforms/fields/core.py", line 204, in validate
    stop_validation = self._run_validation_chain(form, chain)
  File "/home/yani/.local/lib/python2.7/site-packages/wtforms/fields/core.py", line 224, in _run_validation_chain
    validator(form, self)
  File "/home/yani/Documents/TA/SIA/microblog/app/auth/forms.py", line 25, in validate_username
    user = User.query.filter_by(username=username.data).first()
  File "/home/yani/.local/lib/python2.7/site-packages/sqlalchemy/orm/query.py", line 2755, in first
    ret = list(self[0:1])
  File "/home/yani/.local/lib/python2.7/site-packages/sqlalchemy/orm/query.py", line 2547, in __getitem__
    return list(res)
  File "/home/yani/.local/lib/python2.7/site-packages/sqlalchemy/orm/query.py", line 2855, in __iter__
    return self._execute_and_instances(context)
  File "/home/yani/.local/lib/python2.7/site-packages/sqlalchemy/orm/query.py", line 2878, in _execute_and_instances
    result = conn.execute(querycontext.statement, self._params)
  File "/home/yani/.local/lib/python2.7/site-packages/sqlalchemy/engine/base.py", line 945, in execute
    return meth(self, multiparams, params)
  File "/home/yani/.local/lib/python2.7/site-packages/sqlalchemy/sql/elements.py", line 263, in _execute_on_connection
    return connection._execute_clauseelement(self, multiparams, params)
  File "/home/yani/.local/lib/python2.7/site-packages/sqlalchemy/engine/base.py", line 1053, in _execute_clauseelement
    compiled_sql, distilled_params
  File "/home/yani/.local/lib/python2.7/site-packages/sqlalchemy/engine/base.py", line 1189, in _execute_context
    context)
  File "/home/yani/.local/lib/python2.7/site-packages/sqlalchemy/engine/base.py", line 1402, in _handle_dbapi_exception
    exc_info
  File "/home/yani/.local/lib/python2.7/site-packages/sqlalchemy/util/compat.py", line 203, in raise_from_cause
    reraise(type(exception), exception, tb=exc_tb, cause=cause)
  File "/home/yani/.local/lib/python2.7/site-packages/sqlalchemy/engine/base.py", line 1182, in _execute_context
    context)
  File "/home/yani/.local/lib/python2.7/site-packages/sqlalchemy/engine/default.py", line 470, in do_execute
    cursor.execute(statement, parameters)
OperationalError: (sqlite3.OperationalError) no such table: user [SQL: u'SELECT user.id AS user_id, user.username AS user_username, user.email AS user_email, user.password_hash AS user_password_hash, user.about_me AS user_about_me, user.last_seen AS user_last_seen, user.token AS user_token, user.token_expiration AS user_token_expiration, user.last_message_read_time AS user_last_message_read_time \nFROM user \nWHERE user.username = ?\n LIMIT ? OFFSET ?'] [parameters: (u'test', 1, 0)]
2019-01-31 15:11:31,844 INFO: Microblog startup [in /home/yani/Documents/TA/SIA/microblog/app/__init__.py:89]
2019-01-31 15:12:29,366 INFO: Microblog startup [in /home/yani/Documents/TA/SIA/microblog/app/__init__.py:89]
2019-01-31 15:12:53,896 INFO: Microblog startup [in /home/yani/Documents/TA/SIA/microblog/app/__init__.py:89]
2019-01-31 15:13:22,934 INFO: Microblog startup [in /home/yani/Documents/TA/SIA/microblog/app/__init__.py:89]
2019-01-31 15:13:41,415 INFO: Microblog startup [in /home/yani/Documents/TA/SIA/microblog/app/__init__.py:89]
2019-01-31 15:13:55,348 INFO: Microblog startup [in /home/yani/Documents/TA/SIA/microblog/app/__init__.py:89]
2019-01-31 15:13:59,803 INFO: Microblog startup [in /home/yani/Documents/TA/SIA/microblog/app/__init__.py:89]
2019-01-31 16:34:26,168 INFO: Microblog startup [in /home/yani/Documents/TA/SIA/microblog/app/__init__.py:89]
